{
    "error": {
        "http_code": 404,
        "message": "Cannot find S3 cluster for storage cluster",
        "traceback": [
            "Traceback (most recent call last):\n",
            "  File \"/usr/libexec/vstorage-ui-backend/venv/lib64/python3.4/site-packages/vstorage_ui_backend-1.3.185-py3.4.egg/backend/business/models/s3/users/services.py\", line 33, in add_user\n    self.get_user_by_email(cluster_id, email)\n",
            "  File \"/usr/libexec/vstorage-ui-backend/venv/lib64/python3.4/site-packages/vstorage_ui_backend-1.3.185-py3.4.egg/backend/business/models/s3/users/services.py\", line 27, in get_user_by_email\n    user = S3UserFinder(logger).find_by_email(cluster_id, email)\n",
            "  File \"/usr/libexec/vstorage-ui-backend/venv/lib64/python3.4/site-packages/vstorage_ui_backend-1.3.185-py3.4.egg/backend/business/models/s3/users/users.py\", line 197, in find_by_email\n    user_data = self._user_gateway.find_by_email(cluster_id, email)\n",
            "  File \"/usr/libexec/vstorage-ui-backend/venv/lib64/python3.4/site-packages/vstorage_ui_backend-1.3.185-py3.4.egg/backend/business/models/s3/users/users.py\", line 41, in find_by_email\n    return self._request(cluster_id, query, email)\n",
            "  File \"/usr/libexec/vstorage-ui-backend/venv/lib64/python3.4/site-packages/vstorage_ui_backend-1.3.185-py3.4.egg/backend/business/models/s3/users/users.py\", line 21, in _request\n    raise ObjectDoesNotExist('Cannot find S3 cluster for storage cluster')\n",
            "backend.business.models.exceptions.ObjectDoesNotExist: Cannot find S3 cluster for storage cluster\n",
            "\nDuring handling of the above exception, another exception occurred:\n\n",
            "Traceback (most recent call last):\n",
            "  File \"/usr/libexec/vstorage-ui-backend/venv/lib64/python3.4/site-packages/vstorage_ui_backend-1.3.185-py3.4.egg/backend/presentation/decorators.py\", line 28, in wrapper\n    return func(*args, **kwargs)\n",
            "  File \"/usr/libexec/vstorage-ui-backend/venv/lib64/python3.4/site-packages/vstorage_ui_backend-1.3.185-py3.4.egg/backend/presentation/s3/users.py\", line 58, in post\n    user = create_s3_users_service(logger).add_user(cluster_id, **payload)\n",
            "  File \"/usr/libexec/vstorage-ui-backend/venv/lib64/python3.4/site-packages/vstorage_ui_backend-1.3.185-py3.4.egg/backend/business/models/s3/users/services.py\", line 36, in add_user\n    user.save()\n",
            "  File \"/usr/libexec/vstorage-ui-backend/venv/lib64/python3.4/site-packages/vstorage_ui_backend-1.3.185-py3.4.egg/backend/business/models/s3/users/users.py\", line 134, in save\n    user_data = self._user_gateway.create(self.cluster_id, self.email, self.is_enabled, self.description)\n",
            "  File \"/usr/libexec/vstorage-ui-backend/venv/lib64/python3.4/site-packages/vstorage_ui_backend-1.3.185-py3.4.egg/backend/business/models/s3/users/users.py\", line 47, in create\n    return self._request(cluster_id, query, dict(email=email, is_enabled=is_enabled, description=description))\n",
            "  File \"/usr/libexec/vstorage-ui-backend/venv/lib64/python3.4/site-packages/vstorage_ui_backend-1.3.185-py3.4.egg/backend/business/models/s3/users/users.py\", line 21, in _request\n    raise ObjectDoesNotExist('Cannot find S3 cluster for storage cluster')\n",
            "backend.business.models.exceptions.ObjectDoesNotExist: Cannot find S3 cluster for storage cluster\n"
        ],
        "subsytem": "presentation",
        "errors": null
    },
    "message": "Cannot find S3 cluster for storage cluster (Deprecated field)"
}